<?xml version="1.0"?>
<robot name="lio_sam_robot">

  <!-- Base Link -->
  <link name="base_link">
    <visual>
      <geometry>
        <box size="0.8 0.6 0.3"/>
      </geometry>
      <material name="blue">
        <color rgba="0.2 0.2 0.8 1.0"/>
      </material>
    </visual>
    <collision>
      <geometry>
        <box size="0.8 0.6 0.3"/>
      </geometry>
    </collision>
    <inertial>
      <mass value="10.0"/>
      <inertia ixx="0.5" ixy="0.0" ixz="0.0" iyy="0.8" iyz="0.0" izz="0.9"/>
    </inertial>
  </link>

  <!-- Livox MID360 LiDAR -->
  <link name="livox_frame">
    <visual>
      <geometry>
        <cylinder radius="0.08" length="0.1"/>
      </geometry>
      <material name="black">
        <color rgba="0.1 0.1 0.1 1.0"/>
      </material>
    </visual>
    <collision>
      <geometry>
        <cylinder radius="0.08" length="0.1"/>
      </geometry>
    </collision>
    <inertial>
      <mass value="0.5"/>
      <inertia ixx="0.01" ixy="0.0" ixz="0.0" iyy="0.01" iyz="0.0" izz="0.01"/>
    </inertial>
  </link>

  <joint name="livox_joint" type="fixed">
    <parent link="base_link"/>
    <child link="livox_frame"/>
    <origin xyz="0.0 0.0 0.25" rpy="0.0 0.0 0.0"/>
  </joint>

  <!-- IMU -->
  <link name="imu_link">
    <visual>
      <geometry>
        <box size="0.05 0.05 0.02"/>
      </geometry>
      <material name="red">
        <color rgba="0.8 0.1 0.1 1.0"/>
      </material>
    </visual>
    <collision>
      <geometry>
        <box size="0.05 0.05 0.02"/>
      </geometry>
    </collision>
    <inertial>
      <mass value="0.1"/>
      <inertia ixx="0.001" ixy="0.0" ixz="0.0" iyy="0.001" iyz="0.0" izz="0.001"/>
    </inertial>
  </link>

  <joint name="imu_joint" type="fixed">
    <parent link="base_link"/>
    <child link="imu_link"/>
    <origin xyz="0.0 0.0 0.1" rpy="0.0 0.0 0.0"/>
  </joint>

  <!-- Wheels for differential drive -->
  <link name="left_wheel">
    <visual>
      <geometry>
        <cylinder radius="0.1" length="0.05"/>
      </geometry>
      <material name="gray">
        <color rgba="0.5 0.5 0.5 1.0"/>
      </material>
    </visual>
    <collision>
      <geometry>
        <cylinder radius="0.1" length="0.05"/>
      </geometry>
    </collision>
    <inertial>
      <mass value="0.5"/>
      <inertia ixx="0.01" ixy="0.0" ixz="0.0" iyy="0.01" iyz="0.0" izz="0.01"/>
    </inertial>
  </link>

  <link name="right_wheel">
    <visual>
      <geometry>
        <cylinder radius="0.1" length="0.05"/>
      </geometry>
      <material name="gray">
        <color rgba="0.5 0.5 0.5 1.0"/>
      </material>
    </visual>
    <collision>
      <geometry>
        <cylinder radius="0.1" length="0.05"/>
      </geometry>
    </collision>
    <inertial>
      <mass value="0.5"/>
      <inertia ixx="0.01" ixy="0.0" ixz="0.0" iyy="0.01" iyz="0.0" izz="0.01"/>
    </inertial>
  </link>

  <joint name="left_wheel_joint" type="continuous">
    <parent link="base_link"/>
    <child link="left_wheel"/>
    <origin xyz="0.0 0.3 -0.15" rpy="1.57 0.0 0.0"/>
    <axis xyz="0 0 1"/>
  </joint>

  <joint name="right_wheel_joint" type="continuous">
    <parent link="base_link"/>
    <child link="right_wheel"/>
    <origin xyz="0.0 -0.3 -0.15" rpy="1.57 0.0 0.0"/>
    <axis xyz="0 0 1"/>
  </joint>

  <!-- Caster Wheel -->
  <link name="caster_wheel">
    <visual>
      <geometry>
        <sphere radius="0.05"/>
      </geometry>
      <material name="gray">
        <color rgba="0.5 0.5 0.5 1.0"/>
      </material>
    </visual>
    <collision>
      <geometry>
        <sphere radius="0.05"/>
      </geometry>
    </collision>
    <inertial>
      <mass value="0.1"/>
      <inertia ixx="0.001" ixy="0.0" ixz="0.0" iyy="0.001" iyz="0.0" izz="0.001"/>
    </inertial>
  </link>

  <joint name="caster_wheel_joint" type="fixed">
    <parent link="base_link"/>
    <child link="caster_wheel"/>
    <origin xyz="0.3 0.0 -0.15" rpy="0.0 0.0 0.0"/>
  </joint>

  <!-- Gazebo Plugin for Differential Drive -->
  <gazebo>
    <plugin name="diff_drive" filename="libgazebo_ros_diff_drive.so">
      <ros>
        <namespace>/</namespace>
        <remapping>cmd_vel:=cmd_vel</remapping>
        <remapping>odom:=odom</remapping>
      </ros>
      <update_rate>50</update_rate>
      <left_joint>left_wheel_joint</left_joint>
      <right_joint>right_wheel_joint</right_joint>
      <wheel_separation>0.6</wheel_separation>
      <wheel_diameter>0.2</wheel_diameter>
      <max_wheel_torque>20</max_wheel_torque>
      <max_wheel_acceleration>1.0</max_wheel_acceleration>
      <publish_odom>true</publish_odom>
      <publish_odom_tf>true</publish_odom_tf>
      <publish_wheel_tf>true</publish_wheel_tf>
      <odometry_frame>odom</odometry_frame>
      <robot_base_frame>base_link</robot_base_frame>
    </plugin>
  </gazebo>

  <!-- Gazebo Plugin for IMU -->
  <gazebo reference="imu_link">
    <sensor name="imu_sensor" type="imu">
      <always_on>true</always_on>
      <update_rate>100</update_rate>
      <visualize>true</visualize>
      <imu>
        <angular_velocity_x>
          <noise type="gaussian">
            <mean>0.0</mean>
            <stddev>0.02</stddev>
          </noise>
        </angular_velocity_x>
        <angular_velocity_y>
          <noise type="gaussian">
            <mean>0.0</mean>
            <stddev>0.02</stddev>
          </noise>
        </angular_velocity_y>
        <angular_velocity_z>
          <noise type="gaussian">
            <mean>0.0</mean>
            <stddev>0.02</stddev>
          </noise>
        </angular_velocity_z>
        <linear_acceleration_x>
          <noise type="gaussian">
            <mean>0.0</mean>
            <stddev>0.1</stddev>
          </noise>
        </linear_acceleration_x>
        <linear_acceleration_y>
          <noise type="gaussian">
            <mean>0.0</mean>
            <stddev>0.1</stddev>
          </noise>
        </linear_acceleration_y>
        <linear_acceleration_z>
          <noise type="gaussian">
            <mean>0.0</mean>
            <stddev>0.1</stddev>
          </noise>
        </linear_acceleration_z>
      </imu>
      <plugin name="imu_plugin" filename="libgazebo_ros_imu_sensor.so">
        <ros>
          <namespace>/</namespace>
          <remapping>~/imu:=imu</remapping>
        </ros>
        <frame_name>imu_link</frame_name>
      </plugin>
    </sensor>
  </gazebo>

  <!-- Gazebo Plugin for LiDAR -->
  <gazebo reference="livox_frame">
    <sensor name="livox_sensor" type="ray">
      <always_on>true</always_on>
      <visualize>true</visualize>
      <update_rate>10</update_rate>
      <ray>
        <scan>
          <horizontal>
            <samples>360</samples>
            <resolution>1</resolution>
            <min_angle>-1.57</min_angle>
            <max_angle>1.57</max_angle>
          </horizontal>
          <vertical>
            <samples>64</samples>
            <resolution>1</resolution>
            <min_angle>-0.5</min_angle>
            <max_angle>0.5</max_angle>
          </vertical>
        </scan>
        <range>
          <min>0.1</min>
          <max>100.0</max>
          <resolution>0.01</resolution>
        </range>
        <noise>
          <type>gaussian</type>
          <mean>0.0</mean>
          <stddev>0.01</stddev>
        </noise>
      </ray>
      <plugin name="livox_plugin" filename="libgazebo_ros_ray_sensor.so">
        <ros>
          <namespace>/</namespace>
          <remapping>~/scan:=points_cloud</remapping>
        </ros>
        <output_type>sensor_msgs/PointCloud2</output_type>
        <frame_name>livox_frame</frame_name>
      </plugin>
    </sensor>
  </gazebo>

  <!-- Gazebo materials -->
  <material name="blue">
    <color rgba="0.2 0.2 0.8 1.0"/>
  </material>
  
  <material name="black">
    <color rgba="0.1 0.1 0.1 1.0"/>
  </material>
  
  <material name="red">
    <color rgba="0.8 0.1 0.1 1.0"/>
  </material>
  
  <material name="gray">
    <color rgba="0.5 0.5 0.5 1.0"/>
  </material>

</robot>