<?xml version="1.0" ?>
<!-- =================================================================================== -->
<!-- |    This document was autogenerated by xacro from /home/ywj/dog_slam/LIO-SAM_MID360_ROS2_PKG/ros2/src/ros2_livox_simulation/urdf/my_robot/my_robot.xacro | -->
<!-- |    EDITING THIS FILE BY HAND IS NOT RECOMMENDED                                 | -->
<!-- =================================================================================== -->
<robot name="mid360_robot">
  <!-- =============== base link =============== -->
  <link name="base_footprint"/>
  <link name="base_link">
    <visual>
      <origin rpy="0 0 0" xyz="0 0 0"/>
      <geometry>
        <box size="0.24 0.1 0.08"/>
      </geometry>
      <material name="base_link_mat">
        <color rgba="1.0 1.0 1.0 0.5"/>
      </material>
    </visual>
    <collision>
      <origin rpy="0 0 0" xyz="0 0 0"/>
      <geometry>
        <box size="0.24 0.1 0.08"/>
      </geometry>
      <material name="base_link_mat">
        <color rgba="1.0 1.0 1.0 0.5"/>
      </material>
    </collision>
    <inertial>
      <mass value="1.0"/>
      <origin xyz="0 0 0"/>
      <inertia ixx="0.01" ixy="0.0" ixz="0.0" iyy="0.01" iyz="0.0" izz="0.01"/>
    </inertial>
  </link>
  <joint name="base_link_joint" type="fixed">
    <parent link="base_footprint"/>
    <child link="base_link"/>
    <origin rpy="0 0 0" xyz="0 0 0.04"/>
  </joint>
  <!-- =============== base link =============== -->
  <link name="bhind_left_wheel">
    <visual>
      <origin rpy="1.57079 0 0" xyz="0 0 0"/>
      <geometry>
        <cylinder length="0.032" radius="0.04"/>
      </geometry>
      <material name="bhind_left_wheel_mat">
        <color rgba="0.0 0.0 0.0 1.0"/>
      </material>
    </visual>
    <collision>
      <origin rpy="1.57079 0 0" xyz="0 0 0"/>
      <geometry>
        <cylinder length="0.032" radius="0.04"/>
      </geometry>
      <material name="bhind_left_wheel_mat">
        <color rgba="0.0 0.0 0.0 1.0"/>
      </material>
    </collision>
    <inertial>
      <mass value="1.0"/>
      <origin xyz="0 0 0"/>
      <inertia ixx="0.01" ixy="0.0" ixz="0.0" iyy="0.01" iyz="0.0" izz="0.01"/>
    </inertial>
  </link>
  <joint name="bhind_left_wheel_joint" type="continuous">
    <parent link="base_link"/>
    <child link="bhind_left_wheel"/>
    <origin rpy="0 0 0" xyz="-0.08 0.07 -0.04"/>
    <axis xyz="0 1 0"/>
  </joint>
  <link name="bhind_right_wheel">
    <visual>
      <origin rpy="1.57079 0 0" xyz="0 0 0"/>
      <geometry>
        <cylinder length="0.032" radius="0.04"/>
      </geometry>
      <material name="bhind_right_wheel_mat">
        <color rgba="0.0 0.0 0.0 1.0"/>
      </material>
    </visual>
    <collision>
      <origin rpy="1.57079 0 0" xyz="0 0 0"/>
      <geometry>
        <cylinder length="0.032" radius="0.04"/>
      </geometry>
      <material name="bhind_right_wheel_mat">
        <color rgba="0.0 0.0 0.0 1.0"/>
      </material>
    </collision>
    <inertial>
      <mass value="1.0"/>
      <origin xyz="0 0 0"/>
      <inertia ixx="0.01" ixy="0.0" ixz="0.0" iyy="0.01" iyz="0.0" izz="0.01"/>
    </inertial>
  </link>
  <joint name="bhind_right_wheel_joint" type="continuous">
    <parent link="base_link"/>
    <child link="bhind_right_wheel"/>
    <origin rpy="0 0 0" xyz="-0.08 -0.07 -0.04"/>
    <axis xyz="0 1 0"/>
  </joint>
  <link name="ahead_left_wheel">
    <visual>
      <origin rpy="1.57079 0 0" xyz="0 0 0"/>
      <geometry>
        <cylinder length="0.032" radius="0.04"/>
      </geometry>
      <material name="ahead_left_wheel_mat">
        <color rgba="0.0 0.0 0.0 1.0"/>
      </material>
    </visual>
    <collision>
      <origin rpy="1.57079 0 0" xyz="0 0 0"/>
      <geometry>
        <cylinder length="0.032" radius="0.04"/>
      </geometry>
      <material name="ahead_left_wheel_mat">
        <color rgba="0.0 0.0 0.0 1.0"/>
      </material>
    </collision>
    <inertial>
      <mass value="1.0"/>
      <origin xyz="0 0 0"/>
      <inertia ixx="0.01" ixy="0.0" ixz="0.0" iyy="0.01" iyz="0.0" izz="0.01"/>
    </inertial>
  </link>
  <joint name="ahead_left_wheel_joint" type="continuous">
    <parent link="base_link"/>
    <child link="ahead_left_wheel"/>
    <origin rpy="0 0 0" xyz="0.08 0.07 -0.04"/>
    <axis xyz="0 1 0"/>
  </joint>
  <link name="ahead_right_wheel">
    <visual>
      <origin rpy="1.57079 0 0" xyz="0 0 0"/>
      <geometry>
        <cylinder length="0.032" radius="0.04"/>
      </geometry>
      <material name="ahead_right_wheel_mat">
        <color rgba="0.0 0.0 0.0 1.0"/>
      </material>
    </visual>
    <collision>
      <origin rpy="1.57079 0 0" xyz="0 0 0"/>
      <geometry>
        <cylinder length="0.032" radius="0.04"/>
      </geometry>
      <material name="ahead_right_wheel_mat">
        <color rgba="0.0 0.0 0.0 1.0"/>
      </material>
    </collision>
    <inertial>
      <mass value="1.0"/>
      <origin xyz="0 0 0"/>
      <inertia ixx="0.01" ixy="0.0" ixz="0.0" iyy="0.01" iyz="0.0" izz="0.01"/>
    </inertial>
  </link>
  <joint name="ahead_right_wheel_joint" type="continuous">
    <parent link="base_link"/>
    <child link="ahead_right_wheel"/>
    <origin rpy="0 0 0" xyz="0.08 -0.07 -0.04"/>
    <axis xyz="0 1 0"/>
  </joint>
  <!-- =============== 轮子配置 =============== -->
  <link name="livox_frame">
    <visual>
      <origin rpy="1.5707963267948966 0 3.141592653589793" xyz="0.025 -0.0265 -0.025"/>
      <geometry>
        <mesh filename="package://ros2_livox_simulation/meshes/mid360.stl" scale="0.0008 0.0008 0.0008"/>
      </geometry>
    </visual>
    <collision>
      <origin rpy="1.5707963267948966 0 3.141592653589793" xyz="0.025 -0.0265 -0.025"/>
      <geometry>
        <mesh filename="package://ros2_livox_simulation/meshes/mid360.stl" scale="0.0008 0.0008 0.0008"/>
      </geometry>
    </collision>
    <inertial>
      <origin rpy="1.5707963267948966 0 1.5707963267948966" xyz="0 0 0"/>
      <mass value="0.4"/>
      <inertia ixx="0.00045333333333333337" ixy="0.0" ixz="0.0" iyy="0.00045333333333333337" iyz="0.0" izz="0.00023999999999999998"/>
    </inertial>
  </link>
  <joint name="livox_frame_joint" type="fixed">
    <parent link="base_link"/>
    <child link="livox_frame"/>
    <origin rpy="0.0 0 0.0" xyz="0.0 0.0 0.06"/>
  </joint>
  <gazebo reference="livox_frame">
    <sensor name="livox_frame" type="ray">
      <pose>0 0 0 0 0 0</pose>
      <visualize>true</visualize>
      <update_rate>10</update_rate>
      <plugin filename="libros2_livox.so" name="livox_frame_plugin">
        <topic>/livox/lidar</topic>
        <xfer_format>1</xfer_format>
        <!-- 设置为1表示Livox私有格式 -->
        <enable_intensity>true</enable_intensity>
        <intensity_mean>100</intensity_mean>
        <!-- 强度均值（0-255，根据需求调整） -->
        <intensity_stddev>5</intensity_stddev>
        <!-- 强度噪声（模拟真实波动） -->
        <ray>
          <scan>
            <horizontal>
              <samples>100</samples>
              <resolution>1</resolution>
              <min_angle>0</min_angle>
              <max_angle>6.2831852</max_angle>
            </horizontal>
            <vertical>
              <samples>360</samples>
              <resolution>1</resolution>
              <min_angle>-0.12601276984444446</min_angle>
              <max_angle>0.9637707965111111</max_angle>
            </vertical>
          </scan>
          <range>
            <min>0.1</min>
            <max>200.0</max>
            <resolution>0.002</resolution>
          </range>
          <noise>
            <type>gaussian</type>
            <mean>0.0</mean>
            <stddev>0.002</stddev>
          </noise>
        </ray>
        <visualize>false</visualize>
        <samples>30000</samples>
        <downsample>10</downsample>
        <csv_file_name>/home/ywj/dog_slam/LIO-SAM_MID360_ROS2_PKG/ros2/install/ros2_livox_simulation/share/ros2_livox_simulation/scan_mode/mid360.csv</csv_file_name>
        <topic>/livox/lidar</topic>
      </plugin>
    </sensor>
  </gazebo>
  <!-- =============== mid360 ============ -->
  <link name="imu_link">
    <visual>
      <origin rpy="0 0 0" xyz="0 0 0"/>
      <geometry>
        <box size="0.02 0.02 0.02"/>
      </geometry>
      <material name="imu_link_mat">
        <color rgba="1.0 1.0 0.0 1.0"/>
      </material>
    </visual>
    <collision>
      <origin rpy="0 0 0" xyz="0 0 0"/>
      <geometry>
        <box size="0.02 0.02 0.02"/>
      </geometry>
      <material name="imu_link_mat">
        <color rgba="1.0 1.0 0.0 1.0"/>
      </material>
    </collision>
    <inertial>
      <mass value="1.0"/>
      <origin xyz="0 0 0"/>
      <inertia ixx="0.01" ixy="0.0" ixz="0.0" iyy="0.01" iyz="0.0" izz="0.01"/>
    </inertial>
  </link>
  <joint name="imu_link_joint" type="fixed">
    <parent link="base_link"/>
    <child link="imu_link"/>
    <origin rpy="0 0 0" xyz="0 0 0.02"/>
  </joint>
  <link name="camera_link">
    <visual>
      <origin rpy="0 0 0" xyz="0 0 0"/>
      <geometry>
        <box size="0.02 0.1 0.02"/>
      </geometry>
      <material name="camera_link_mat">
        <color rgba="0.0 0.0 0.0 1.0"/>
      </material>
    </visual>
    <collision>
      <origin rpy="0 0 0" xyz="0 0 0"/>
      <geometry>
        <box size="0.02 0.1 0.02"/>
      </geometry>
      <material name="camera_link_mat">
        <color rgba="0.0 0.0 0.0 1.0"/>
      </material>
    </collision>
    <inertial>
      <mass value="1.0"/>
      <origin xyz="0 0 0"/>
      <inertia ixx="0.01" ixy="0.0" ixz="0.0" iyy="0.01" iyz="0.0" izz="0.01"/>
    </inertial>
  </link>
  <joint name="camera_link_joint" type="fixed">
    <parent link="base_link"/>
    <child link="camera_link"/>
    <origin rpy="0 0 0" xyz="0.1 0.0 0.05"/>
  </joint>
  <!-- =============== 传感器 ============ -->
  <!-- =============== 导入gazebo插件 ============ -->
  <gazebo reference="camera_link">
    <sensor name="camera_sensor" type="depth">
      <plugin filename="libgazebo_ros_camera.so" name="depth_camera">
        <frame_name>camera_optical_link</frame_name>
      </plugin>
      <always_on>true</always_on>
      <update_rate>10</update_rate>
      <camera name="camera">
        <horizontal_fov>1.5009831567</horizontal_fov>
        <image>
          <width>800</width>
          <height>600</height>
          <format>R8G8B8</format>
        </image>
        <distortion>
          <k1>0.0</k1>
          <k2>0.0</k2>
          <k3>0.0</k3>
          <p1>0.0</p1>
          <p2>0.0</p2>
          <center>0.5 0.5</center>
        </distortion>
      </camera>
    </sensor>
  </gazebo>
  <!-- =============== 导入gazebo插件 ============ -->
  <!-- =============== 使用插件 ============ -->
  <ros2_control name="MyRobotPlanarSystem" type="system">
    <hardware>
      <plugin>gazebo_ros2_control/GazeboSystem</plugin>
    </hardware>
  </ros2_control>
  <gazebo>
    <!-- libgazebo_ros_planar_move.so 是 平面移动插件 -->
    <plugin filename="libgazebo_ros_planar_move.so" name="planar_move">
      <ros>
        <namespace>/</namespace>
        <remapping>cmd_vel:=cmd_vel</remapping>
        <remapping>odom:=odom</remapping>
      </ros>
      <!-- 频率 -->
      <update_rate>30</update_rate>
      <!-- 里程计frame id -->
      <odometry_frame>odom</odometry_frame>
      <!-- 是否发布里程计 -  -->
      <publish_odom>false</publish_odom>
      <!-- 是否发布里程计tf -->
      <publish_odom_tf>false</publish_odom_tf>
      <robot_base_frame>base_footprint</robot_base_frame>
      <!-- 最大速度 -->
      <max_vel_x>5.0</max_vel_x>
      <max_vel_y>5.0</max_vel_y>
      <max_vel_theta>3.14</max_vel_theta>
      <!-- 最大加速度 -->
      <max_accel_x>3.0</max_accel_x>
      <max_accel_y>3.0</max_accel_y>
      <max_accel_theta>3.14</max_accel_theta>
    </plugin>
  </gazebo>
  <gazebo reference="imu_link">
    <sensor name="imu_sensor" type="imu">
      <plugin filename="libgazebo_ros_imu_sensor.so" name="imu_plugin">
        <ros>
          <namespace>/</namespace>
          <remapping>~/out:=/livox/imu</remapping>
        </ros>
        <initial_orientation_as_reference>false</initial_orientation_as_reference>
      </plugin>
      <update_rate>100</update_rate>
      <always_on>true</always_on>
      <!-- 六轴噪声设置 -->
      <imu>
        <angular_velocity>
          <x>
            <noise type="gaussian">
              <mean>0.0</mean>
              <stddev>2e-4</stddev>
              <bias_mean>0.0000075</bias_mean>
              <bias_stddev>0.0000008</bias_stddev>
            </noise>
          </x>
          <y>
            <noise type="gaussian">
              <mean>0.0</mean>
              <stddev>2e-4</stddev>
              <bias_mean>0.0000075</bias_mean>
              <bias_stddev>0.0000008</bias_stddev>
            </noise>
          </y>
          <z>
            <noise type="gaussian">
              <mean>0.0</mean>
              <stddev>2e-4</stddev>
              <bias_mean>0.0000075</bias_mean>
              <bias_stddev>0.0000008</bias_stddev>
            </noise>
          </z>
        </angular_velocity>
        <linear_acceleration>
          <x>
            <noise type="gaussian">
              <mean>0.0</mean>
              <stddev>1.7e-2</stddev>
              <bias_mean>0.1</bias_mean>
              <bias_stddev>0.001</bias_stddev>
            </noise>
          </x>
          <y>
            <noise type="gaussian">
              <mean>0.0</mean>
              <stddev>1.7e-2</stddev>
              <bias_mean>0.1</bias_mean>
              <bias_stddev>0.001</bias_stddev>
            </noise>
          </y>
          <z>
            <noise type="gaussian">
              <mean>0.0</mean>
              <stddev>1.7e-2</stddev>
              <bias_mean>0.1</bias_mean>
              <bias_stddev>0.001</bias_stddev>
            </noise>
          </z>
        </linear_acceleration>
      </imu>
    </sensor>
  </gazebo>
</robot>
